Traceback (most recent call last):
  File "C:\Users\pipon\Desktop\proyecto_huevos\.venv\Lib\site-packages\pandas\core\indexes\base.py", line 3812, in get_loc
    return self._engine.get_loc(casted_key)
           ^^^^^^^^^^^^^^^^^^^^^^^^^^^^^^^^
  File "pandas/_libs/index.pyx", line 167, in pandas._libs.index.IndexEngine.get_loc
  File "pandas/_libs/index.pyx", line 196, in pandas._libs.index.IndexEngine.get_loc
  File "pandas/_libs/hashtable_class_helper.pxi", line 7088, in pandas._libs.hashtable.PyObjectHashTable.get_item
  File "pandas/_libs/hashtable_class_helper.pxi", line 7096, in pandas._libs.hashtable.PyObjectHashTable.get_item
KeyError: 'date'

The above exception was the direct cause of the following exception:

Traceback (most recent call last):
  File "<frozen runpy>", line 198, in _run_module_as_main
  File "<frozen runpy>", line 88, in _run_code
  File "C:\Users\pipon\Desktop\proyecto_huevos\upgrade_precision\pipeline\pipeline_monthly_exog.py", line 286, in <module>
    main()
  File "C:\Users\pipon\Desktop\proyecto_huevos\upgrade_precision\pipeline\pipeline_monthly_exog.py", line 141, in main
    X = make_X(L)
        ^^^^^^^^^
  File "C:\Users\pipon\Desktop\proyecto_huevos\upgrade_precision\pipeline\pipeline_monthly_exog.py", line 135, in make_X
    return _build_exog_aligned(y_deseas.index, paths, lags=lags, log_names=LOG_NAMES)
           ^^^^^^^^^^^^^^^^^^^^^^^^^^^^^^^^^^^^^^^^^^^^^^^^^^^^^^^^^^^^^^^^^^^^^^^^^^
  File "C:\Users\pipon\Desktop\proyecto_huevos\upgrade_precision\pipeline\pipeline_monthly_exog.py", line 55, in _build_exog_aligned
    s = _load_align_series(p, y_index)
        ^^^^^^^^^^^^^^^^^^^^^^^^^^^^^^
  File "C:\Users\pipon\Desktop\proyecto_huevos\upgrade_precision\pipeline\pipeline_monthly_exog.py", line 42, in _load_align_series
    s = read_series_csv(path).asfreq("MS")
        ^^^^^^^^^^^^^^^^^^^^^
  File "C:\Users\pipon\Desktop\proyecto_huevos\upgrade_precision\utils\io_tools.py", line 7, in read_series_csv
    df[date_col] = pd.to_datetime(df[date_col])
                                  ~~^^^^^^^^^^
  File "C:\Users\pipon\Desktop\proyecto_huevos\.venv\Lib\site-packages\pandas\core\frame.py", line 4107, in __getitem__
    indexer = self.columns.get_loc(key)
              ^^^^^^^^^^^^^^^^^^^^^^^^^
  File "C:\Users\pipon\Desktop\proyecto_huevos\.venv\Lib\site-packages\pandas\core\indexes\base.py", line 3819, in get_loc
    raise KeyError(key) from err
KeyError: 'date'
[STL] aditiva OK (n=61, period=12)
